Workbook
Name bbiomaxmoyen: Calcul_bbio!$E$4
Name categorie: Input_resultats!$E$22
Name cepmaxmoyen: Calcul_energie!$F$4
Name cepnrmaxmoyen: Calcul_energie!$E$4
Name classe_inertie: Input_resultats!$E$29
Name climatisé: Input_resultats!$E$23
Name decret2026: Input_resultats!$G$28
Name depotpc: Input_resultats!$E$15
Name depotPC_année: Enumération!$P$9
Name elevation: Input_resultats!$E$9
Name Enseignement_primaire_ou_secondaire: Enumération!$F$4:$F$5
Name est_igh: Input_resultats!$E$25
Name Etablissements_de_santé: Enumération!$I$4:$I$5
Name expobruit: Input_resultats!$E$14
Name Hôtels: Enumération!$G$4:$G$7
Name HSPmoy: Input_resultats!$E$27
Name icconstructionmaxmoyen: Calcul_matiere!$E$3
Name icded: Input_resultats!$E$19
Name icenergie: Calcul_energie!$L$4
Name iclot1: Input_resultats!$E$16
Name iclot13: Input_resultats!$E$18
Name iclot2: Input_resultats!$E$17
Name ID_usage: Enumération!$H$10
Name Industries_ou_artisanats: Enumération!$J$4:$J$5
Name mbbruit: Calcul_bbio!$E$61
Name mbcombles: Calcul_bbio!$E$46
Name mbgeo: Calcul_bbio!$E$34
Name mbhsp: Calcul_bbio!$E$94
Name mbsurfmoy: Calcul_bbio!$E$48
Name mbsurtot: Calcul_bbio!$E$54
Name mccat: Calcul_energie!$E$99
Name mccombles: Calcul_energie!$E$79
Name mcgeo: Calcul_energie!$E$63
Name mchsp: Calcul_energie!$E$111
Name mcsurfmoy: Calcul_energie!$E$81
Name mcsurftot: Calcul_energie!$E$87
Name miagrément: Calcul_matiere!$E$75
Name miclimrcu: Calcul_matiere!$E$88
Name micombles: Calcul_matiere!$E$37
Name mided: Calcul_matiere!$E$66
Name migeo: Calcul_matiere!$E$25
Name mihsp: Calcul_matiere!$E$81
Name miinfra: Calcul_matiere!$E$52
Name mipv: Calcul_matiere!$E$62
Name misurfmoy: Calcul_matiere!$E$39
Name misurftot: Calcul_matiere!$E$45
Name mivrd: Calcul_matiere!$E$57
Name NL: Input_resultats!$E$12
Name rcu: Input_resultats!$E$20
Name rcu_classe: Input_resultats!$E$21
Name Restaurants: Enumération!$H$4:$H$7
Name Restaurants_scolaires: Enumération!$K$4:$K$5
Name s_existant: 'surélévations et extensions'!$E$8
Name Sagrément: Input_resultats!$E$26
Name scombles: Input_resultats!$E$11
Name seuilded: Calcul_matiere!$F$66
Name smoylgt: Input_resultats!$E$13
Name sref: Input_resultats!$E$10
Name sref_ext: 'surélévations et extensions'!$E$7
Name typo_travaux: 'surélévations et extensions'!$E$5

Sheet Info
B3: 2.2 | K3: avec l'aide du :
C4: Calculatrice des exigences de la RE2020
C6: La RE2020 impose 1 seuil pour chacun des 6 indicateurs.
C7: Mais ces seuils varient en fonction de différentes données comme par exemple la localisation du projet. Un bâtiment dans le sud de la France n'a pas les même contraintes énergétique vu qu'il va moins consommer d'énergie pour se chauffer. Il est donc logique d'adapter les seuils.
C8: Cet outil permet de calculer les seuils des 6 indicateurs
C9: Il est basé sur les textes de loi que l'on peut retrouver par ici
C10: Sinon la page wikipédia donne une partie des informations
C12: version 1.0 - première sortie - février 2025
C13: version 1.01 - rajout d'une mention pour le réseau classé
C14: version 1.02 - erreur dans le Migeo et mi-surfmoy
C15: version 1.03 - micro correction du BBIO pour les bureaux
C16: version 1.1 - ajout du calcul du DH max (+effinergie)
C17: VERSION 2.0 - NOUVEAU USAGES - mars 2026
... C25: 2.1.4 mini bug >=30% et surface dans les surélévations
B26: → | C26: 2.2 - décret 2026-200 appliqué selon la date du PC (nouvelle question ligne 28) ; bornes Mbsurf_moy LC 80/120 m² ; DH_max LC : condition climatisé en H2d/H3 ; dérogation RCU classé pour Icénergie_maxmoyen ; aérogares en catégorie 3 ; messages au lieu des erreurs ; nettoyage des noms cassés
C27: Crédit : Felix Dubois du CSTB pour le passage à la version 2.0 pour les indicateurs carbone et énergie
C29: C'est parti
B30: réalisé par Guillaume Meunier, document non-officiel à utiliser avec toutes les vérifications nécessaires | J30: fichier excel partagé sous licence GNU General Public License (GPL), version 3

Sheet Input_resultats
F1: remplir | G1: le bleu
C2: Les informations nécessaires au calcul
C4: Typologie d'usage → | E4: Logement_collectif | F4: =OR(usage=Enumération!C5,usage=Enumération!C4) -> TRUE
C5: =IF(COUNTIF(Enumération!F3:K3,E4)>0,"typologie précise →","") | E5: partie jour | F5: =IF(ISNUMBER(MATCH(usage,Enumération!F3:K3,0)),IF(ISNUMBER(MATCH(usage_secondaire,INDIRECT(usage),0)),"","Pensez à changer"),"") | I5: =IF(E4=Calcul_bbio!D7,"","ligne uniquement en d'enseignement") -> ligne uniquement en d'enseignement
C6: Département → | D6: nom | E6: Val-d'Oise
C7: (l'un ou l'autre) | D7: n° | E7: - | F7: ="-> "&VLOOKUP(E7,zone[[numéro]:[département]],2,FALSE) -> -> - | I7: attention si vous choisissez un numéro c'est lui qui sera prépondérant dans la zone
C8: Zone climatique | E8: =IF(E7="-",VLOOKUP(E6,zone[[département]:[Valeur]],2,FALSE),VLOOKUP(E7,zone[[numéro]:[Valeur]],3,FALSE)) -> H1a
C9: Elevation → | D9: [m] | E9: <400m | I9: https://www.geoportail.gouv.fr/carte
C10: Surface de référence → | D10: [Sref] | E10: 3800 | F10: =IF(F4,"m² SHAB","m² SU") -> m² SHAB | I10: voir le Guide RE2020 du CEREMA page 48
C11: =IF(usage=Enumération!C4,"Scombles →","") | D11: =IF(usage=Enumération!C4,"[m²]","") | E11: 5 | F11: =IF(usage=Enumération!C4,"m²","") | I11: =IF(usage=Enumération!C4,"Surface de plancher des combles aménagés dont la hauteur sous plafond est inférieure à 1,8 mètres","ligne uniquement en cas de maison") -> ligne uniquement en cas de maison
C12: =IF(F4,"Nombre de logements →","") -> Nombre de logements → | D12: =IF(F4,"[NL]","") -> [NL] | E12: 60 | F12: =IF(F4,"logements","") -> logements | I12: =IF(F4,"Nombre de logements du bâtiment","ligne uniquement en cas de logement") -> Nombre de logements du bâtiment
C13: =IF(F4,"Surface moyenne des logements →","") -> Surface moyenne des logements → | D13: =IF(F4,"[Smoylgt]","") -> [Smoylgt] | E13: =sref/NL -> 63.333333 | F13: =IF(F4,"m² SHAB","") -> m² SHAB | I13: =IF(F4,"surface moyenne des logements du bâtiment ou de la partie de bâtiment, notée Smoylgt, est calculée de la manière suivante : Smoylgt = Sref/ NL","ligne uniquement en cas de logement") -> surface moyenne des logements du bâtiment ou de la partie de bâtiment, notée Smoylgt, est calculée de la manière suivante : Smoylgt = Sref/ NL
C14: Exposition au bruit du bâtiment → | E14: BR1 | I14: dans le chapitre V de https://www.legifrance.gouv.fr/codes/article_lc/LEGIARTI000045292850
C15: Année de dépôt du PC → | E15: 2025 à 2027 | F15: =IF(AND(ID_usage>4,depotPC_année<2024),"PAS LA BONNE DATE","")
C16: Impact lot VRD (1) → | D16: [Iclot1] | E16: 10 | F16: kgCO2e/m²
C17: Impact lot fondation / infra (2) → | D17: [Iclot2] | E17: 30 | F17: kgCO2e/m²
C18: Impact lot photovoltaïque(13) → | D18: [Iclot13] | E18: 0 | F18: kgCO2e/m²
C19: Impact de toutes les DED et forfaits → | D19: [Icded] | E19: 350 | F19: kgCO2e/m² | I19: Pour les bâtiments ou les parties de bâtiments raccordés à un réseau de distribution de chaleur et de froid classé en application de l’article L. 712-1 du code de l’énergie, lorsque la demande de permis de construire correspondante est déposée avant le 31 décembre 2027, le coefficient Icénergie_maxmoyen prend, en fonction de l’usage de la partie de bâtiment, les valeurs définies pour les parties de bâtiments raccordés à un réseau de distribution de chaleur et de froid faisant l'objet d'un permis de construire déposé au cours des années 2022 à 2024.
C20: raccordement à un réseau de chaleur → | E20: NON | F20: =IF(rcu="OUI","Classé ou pas ?","")
C21: Est-ce que ce réseau est classé ? → | E21: OUI | F21: =IF(rcu="OUI","Réseau classé voir à droite","") | G21: =IF(AND(rcu="OUI",rcu_classe="OUI"),TRUE,FALSE) -> FALSE
C22: catégorie de contraintes extérieures → | E22: Catégorie 1 | F22: =IF(categorie="Catégorie 3",IF(OR(ISNUMBER(MATCH(usage,Enumération!Q3:Q11,0)),ISNUMBER(MATCH(usage_detaillé,Enumération!Q3:Q11,0))),"","! pas possible pour cet usage !"),"") | I22: dans le chapitre V partie II de https://www.legifrance.gouv.fr/codes/article_lc/LEGIARTI000045292850
C23: =IF(G21,"climatisé (droit carbone avec RCU) →","climatisé →") -> climatisé → | E23: NON | F23: =IF(AND(categorie="Catégorie 2",climatisé="NON"),"forcément climatisé","") | I23: pour le DH et carbone si RCU classé (pour le DH cela s'applique seulement à des parties de bâtiment)
C25: IGH ? → | E25: NON
C26: Surface cumulée d'agrément → | D26: [m²] | E26: 500 | F26: =IF(Sagrément/sref>0.1,"taux Sref = "&ROUND(Sagrément/sref*100,0)&"%","") -> taux Sref = 13% | I26: la surface cumulée des balcons, des loggias et des terrasses en épannelage du bâtiment ou partie de bâtiment. Les toitures terrasses, terrasses de rez-de-chaussée, de rez-de-jardin, de plain-pied et coursives d’accès extérieur ne sont pas incluses dans cette surface.
C27: Hauteur sous plafond moyenne → | D27: [m] | E27: 2.6 | F27: (fonctionne si >2,5m) | I27: La hauteur sous plafond moyenne, du bâtiment ou de la partie de bâtiment, à usage d’habitation, notée HSPmoy, est la moyenne des hauteurs sous plafond des locaux à usage d’habitation inclus dans la surface de référence pondérée par la surface de référence de ces locaux.
C28: =IF(depotpc="2025 à 2027","PC déposé à partir du 01/07/2026 ? →","") | E28: OUI | F28: =IF(decret2026,"décret 2026-200 appliqué","décret 2026-200 non appliqué") | G28: =OR(depotpc="2028 à 2030",depotpc="à partir de 2031",AND(depotpc="2025 à 2027",E28="OUI")) | I28: Décret n° 2026-200 du 18 mars 2026 (HSP, agrément, Miclim_RCU, IGH) : PC déposés à partir du 1er juillet 2026
C29: classe d'inertie (pour DH effinergie) → | E29: Lourde ou très lourde | I29: (classe d’inertie définit suivant les règles Thbat)
C33: LES SEUILS OBLIGATOIRES
D35: =IF(LEFT(depotpc,1)="à","RE2031","RE"&LEFT(depotpc,4)) -> RE2025
C36: Bioclimatisme : | F36: =Calcul_bbio!E3 -> Bbiomaxmoyen | H36: Mbgéo | J36: Mbcombles | L36: Mbsurf_moy | N36: Mbsurf_tot | P36: Mbbruit | R36: MbHSP
D37: Bbio_max = | E37: =IFERROR(bbiomaxmoyen*(1+mbgeo+mbcombles+mbsurfmoy+mbsurtot+mbbruit+mbhsp),"non applicable") | F37: =bbiomaxmoyen -> 65 | G37: x ( 1 + | H37: =mbgeo -> 0.1 | I37: + | J37: =mbcombles -> 0 | K37: + | L37: =mbsurfmoy -> 0.0051282051 | M37: + | N37: =mbsurtot -> 0 | O37: + | P37: =mbbruit -> 0 | Q37: + | R37: =mbhsp -> 0.026666667 | S37: )
C38: Energie non renouvelable : | F38: Cep,nr_maxmoyen | H38: Mcgéo | J38: Mccombles | L38: Mcsurf_mo | N38: Mcsurf_tot | P38: Mccat | R38: McHSP
D39: Cep,nr_max = | E39: =IFERROR(cepnrmaxmoyen*(1+mcgeo+mccombles+mcsurfmoy+mcsurftot+mccat+mchsp),"non applicable") | F39: =cepnrmaxmoyen -> 70 | G39: x ( 1 + | H39: =mcgeo -> 0.05 | I39: + | J39: =mccombles -> 0 | K39: + | L39: =mcsurfmoy -> -0.011904762 | M39: + | N39: =mcsurftot -> 0 | O39: + | P39: =mccat -> 0 | Q39: + | R39: =mchsp -> 0.01 | S39: )
C40: Consommation d'énergie : | F40: Cep_maxmoyen | H40: Mcgéo | J40: Mccombles | L40: Mcsurf_mo | N40: Mcsurf_tot | P40: Mccat | R40: McHSP
D41: Cep_max = | E41: =IFERROR(cepmaxmoyen*(1+mcgeo+mccombles+mcsurfmoy+mcsurftot+mccat+mchsp),"non applicable") | F41: =cepmaxmoyen -> 85 | G41: x ( 1 + | H41: =mcgeo -> 0.05 | I41: + | J41: =mccombles -> 0 | K41: + | L41: =mcsurfmoy -> -0.011904762 | M41: + | N41: =mcsurftot -> 0 | O41: + | P41: =mccat -> 0 | Q41: + | R41: =mchsp -> 0.01 | S41: )
C42: Impact carbone de l'énergie : | F42: Icénergie_maxmoyen | H42: Mcgéo | J42: Mccombles | L42: Mcsurf_mo | N42: Mcsurf_tot | P42: Mccat | R42: McHSP
D43: Icénergie_max = | E43: =IFERROR(icenergie*(1+mcgeo+mccombles+mcsurfmoy+mcsurftot+mccat+mchsp),"non applicable") | F43: =icenergie -> 260 | G43: x ( 1 + | H43: =mcgeo -> 0.05 | I43: + | J43: =mccombles -> 0 | K43: + | L43: =mcsurfmoy -> -0.011904762 | M43: + | N43: =mcsurftot -> 0 | O43: + | P43: =mccat -> 0 | Q43: + | R43: =mchsp -> 0.01 | S43: )
C44: Impact carbone matière+chantier : | D44: [sur 50 ans] | F44: Icconstruction_maxmoyen | H44: Micombles | J44: Misurf_moy | L44: Misurf_tot | N44: Migeo | P44: Miinfra | R44: Mivrd | T44: Mipv | V44: Mided | X44: Miagrément | Z44: MiHSP | AB44: MiClimRCU
D45: Icconstruction_max = | E45: =IFERROR(icconstructionmaxmoyen*(1+micombles+misurfmoy+misurftot)+migeo+miinfra+mivrd+mipv+mided+miagrément+mihsp+miclimrcu,"non applicable") | F45: =icconstructionmaxmoyen -> 650 | G45: x ( 1 + | H45: =micombles -> 0 | I45: + | J45: =misurfmoy -> 0 | K45: + | L45: =misurftot -> -0.0875 | M45: ) + | N45: =migeo -> 0 | O45: + | P45: =miinfra -> 0 | Q45: + | R45: =mivrd -> 0 | S45: + | T45: =mipv -> 0 | U45: + | V45: =mided -> 0 | W45: + | X45: =miagrément -> 3.4736842 | Y45: + | Z45: =mihsp -> 3.8 | AA45: + | AB45: =miclimrcu -> 0
D46: [sur 50 ans] | V46: ="seuil à "&seuilded -> seuil à 250
...

Sheet surélévations et extensions
F1: remplir | G1: le bleu
C2: Les informations nécessaires connaitre la méthode
C4: Typologie d'usage → | E4: Logement_collectif
C5: Typologie de travaux → | E5: surélévation
C7: Surface travaux (cumulés) → | D7: [Sref] | E7: 160 | F7: =IF(OR(E4=Calcul_bbio!D5,E4=Calcul_bbio!D6),"m² SHAB","m² SU") -> m² SHAB
C8: Surface initiale → | D8: [Sexistant] | E8: 1000 | F8: =F7 -> m² SHAB
C9: Part de l'extension : | E9: =sref_ext/E8 -> 0.16
C13: Quelle méthode pour ces travaux ?
C16: =HLOOKUP(TRUE,C35:H36,2,FALSE) -> RE2020 light : Bbio, Icconstruction et DH
C19: =C36&", voir le : " -> RE2020 light : Bbio, Icconstruction et DH, voir le : | D19: II de l'article 50-3 de l'arrêté du 4 août 2021 >>> | G19: https://www.legifrance.gouv.fr/loda/article_lc/LEGIARTI000050146201/2026-07-02
C20: =F36&", voir le : " -> Des exigences de moyens, voir le : | D20: III de l'article 50-3 de l'arrêté du 4 août 2021 >>> | G20: https://www.legifrance.gouv.fr/loda/article_lc/LEGIARTI000050146201/2026-07-02
C21: Sinon parcourir le Guide DHUP / CEREMA du 9 mai 2025
A24: ↓ CALCUL (masqué) ↓
B27: Typologie | C27: extension | D27: surélévation | E27: surélévation | F27: tout | G27: tout | H27: sinon
B28: Usage | C28: Maison indiv | D28: <> MI | E28: <> MI | F28: tout | G28: <>mi
B29: Sref | C29: >=50 <=80 | D29: >=50 <=150 | E29: >150 | F29: <50 | G29: >=50 <=150
B30: Sext | D30: >30% Sexis | E30: <30% Sexis | G30: <30% Sexis
B31: Calcul Typologie : | C31: =typo_travaux="extension" -> FALSE | D31: =typo_travaux="surélévation" -> TRUE | E31: =typo_travaux="surélévation" -> TRUE | F31: =TRUE -> TRUE | G31: =TRUE -> TRUE
B32: Calcul Usage : | C32: =usage_surelev=Enumération!C4 -> FALSE | D32: =usage_surelev<>Enumération!C4 -> TRUE | E32: =usage_surelev<>Enumération!C4 -> TRUE | F32: =TRUE -> TRUE | G32: =usage_surelev<>Enumération!C4 -> TRUE
B33: Calcul Sref : | C33: =AND(sref_ext>=50,sref_ext<=80) -> FALSE | D33: =AND(sref_ext>=50,sref_ext<=150) -> FALSE | E33: =sref_ext>150 -> TRUE | F33: =sref_ext<50 -> FALSE | G33: =AND(sref_ext>=50,sref_ext<=150) -> FALSE
B34: Calcul Sext : | C34: =TRUE -> TRUE | D34: =E9>=30% -> FALSE | E34: =E9<30% -> TRUE | F34: =TRUE -> TRUE | G34: =E9<30% -> TRUE
B35: RESULTAT | C35: =AND(C31:C34) -> FALSE | D35: =AND(D31:D34) -> FALSE | E35: =AND(E31:E34) -> TRUE | F35: =AND(F31:F34) -> FALSE | G35: =AND(G31:G34) -> FALSE | H35: =NOT(OR(C35:G35)) -> FALSE
C36: RE2020 light : Bbio, Icconstruction et DH | D36: =C36 -> RE2020 light : Bbio, Icconstruction et DH | E36: =D36 -> RE2020 light : Bbio, Icconstruction et DH | F36: Des exigences de moyens | G36: =F36 -> Des exigences de moyens | H36: RE2020
C37: Toutefois, pour les surélévations climatisées situées en zones H2d ou H3, la valeur DHmaxcat estportée à 1400 DH.

Sheet Calcul_dh
B2: Dhmaxcat | C2: =IF(ISNA(VLOOKUP(usage,B3:C29,2,FALSE)),VLOOKUP(usage_detaillé,B3:C29,2,FALSE),VLOOKUP(usage,B3:C29,2,FALSE)) -> 1250 | E2: Dhmaxcat effinergie | F2: =IF(ISNA(VLOOKUP(usage,E3:F6,2,FALSE)),"Ne s'applique pas",VLOOKUP(usage,E3:F6,2,FALSE)) -> 600 | S2: EFFINERGIE BUREAU + SCOLAIRE
B3: =Enumération!C4 -> Maisons_individuelles_ou_accolées | C3: =C32 -> 1250 | E3: =Enumération!C4 -> Maisons_individuelles_ou_accolées | F3: =IF(OR(zoneclim="H2d",zoneclim="H3"),C32,Q8) -> 600
B4: =Enumération!C5 -> Logement_collectif | C4: =C35 -> 1250 | E4: =Enumération!C5 -> Logement_collectif | F4: =IF(OR(zoneclim="H2d",zoneclim="H3"),C35,Q8) -> 600
B5: =Enumération!C6 -> Bureaux | C5: =C43 -> 1150 | E5: =Enumération!C6 -> Bureaux | F5: =IF(OR(zoneclim="H2d",zoneclim="H3",categorie="Catégorie 3"),C43,600) -> 600
B6: =Enumération!C7 -> Enseignement_primaire_ou_secondaire | C6: =C50 -> 900 | E6: =Enumération!C7 -> Enseignement_primaire_ou_secondaire | F6: =IF(OR(zoneclim="H2d",zoneclim="H3",categorie="Catégorie 3"),C50,600) -> 600
B7: =Enumération!C8 -> Médiathèques_et_bibliothèques | C7: =C57 -> 900 | Q7: DM_max_label | R7: Mdh_in | S7: Mdh_br | T7: Mdh_surf
B8: =Enumération!C9 -> Bâtiments_universitaires_d'enseignement_et_de_recherche_et_bâtiments_d’enseignements_atypiques | C8: =C64 -> 900 | Q8: =600+R8+S8+T8 -> 600 | R8: =IF(classe_inertie=Q13,110,0) -> 0 | S8: =IF(expobruit=Calcul_bbio!J63,130,0) -> 0 | T8: =IF(smoylgt<30,140,0) -> 0
B9: =Enumération!E11 -> Hôtels - 0, 1 et 2 étoiles (partie nuit) | C9: =C71 -> 300
B10: =Enumération!E12 -> Hôtels - 3, 4 et 5 étoiles (partie nuit) | C10: =C78 -> 300
B11: =Enumération!E13 -> Hôtels - 0, 1 et 2 étoiles (partie jour) | C11: =C85 -> 1300
B12: =Enumération!E14 -> Hôtels - 3, 4 et 5 étoiles (partie jour) | C12: =C92 -> 1300
B13: =Enumération!C11 -> Etablissements_d'accueil_de_la_petite_enfance | C13: =C99 -> 550 | Q13: Très légère, légère ou moyenne
B14: =Enumération!E16 -> Restaurants - en continu, 18 heures par jour, 7 jours sur 7 | C14: =C106 -> 2500 | Q14: Lourde ou très lourde
B15: =Enumération!E17 -> Restaurants - 1 repas par jour, 5 jours sur 7 | C15: =C113 -> 250
B16: =Enumération!E18 -> Restaurants - 2 repas par jour, 7 jours sur 7 | C16: =C120 -> 1600
B17: =Enumération!E19 -> Restaurants - 2 repas par jour, 6 jours sur 7 | C17: =C127 -> 1250
B18: =Enumération!C13 -> Commerces | C18: =C134 -> 3300
B19: =Enumération!C14 -> Vestiaires seuls | C19: =C141 -> 1000
B20: =Enumération!C15 -> Etablissements_sanitaires_avec_hébergement | C20: =C148 -> 900
B21: =Enumération!E23 -> Etablissements_de_santé - partie nuit | C21: =C155 -> 900
B22: =Enumération!E24 -> Etablissements_de_santé - partie jour | C22: =C162 -> 1250
B23: =Enumération!C17 -> Aérogares | C23: =C169 -> 12100
B24: =Enumération!E26 -> Industries_ou_artisanats - 3x8h | C24: =C176 -> 3200
B25: =Enumération!E27 -> Industries_ou_artisanats - 8h à 18h | C25: =C183 -> 900
B26: =Enumération!C19 -> Etablissements_sportifs_municipaux_ou_scolaires | C26: =C190 -> 2000
B27: =Enumération!E29 -> Restaurants_scolaires - 1 repas par jour, 5 jours sur 7 | C27: =C197 -> 40
B28: =Enumération!E30 -> Restaurants_scolaires - 3 repas par jour, 5 jours sur 7 | C28: =C204 -> 260
B29: =Enumération!C21 -> Etablissements_sportifs_privés | C29: =C211 -> 2000
B31: =IF(usage=B32,"↓↓↓","") | C31: =IF(usage=B32,"↓↓↓","") | G31: Catégorie 1 | H31: Catégorie 2
B32: =B3 -> Maisons_individuelles_ou_accolées | C32: =HLOOKUP(categorie,G31:H32,2,FALSE) -> 1250 | G32: 1250 | H32: 1850
B34: =IF(usage=B35,"↓↓↓","") -> ↓↓↓ | C34: =IF(usage=B35,"↓↓↓","") -> ↓↓↓ | G34: Cat 1 sauf H2d H3 | H34: Cat 1 ET H2d et H3 | I34: Cat 2
B35: =B4 -> Logement_collectif | C35: =VLOOKUP("ICI",F38:I40,MATCH("ICI",F37:I37,0),FALSE) | F35: catégorie → | G35: =IF(categorie=G31,1,0) -> 1 | H35: =IF(categorie=G31,1,0) -> 1 | I35: =IF(categorie=H31,1,0) -> 0
B36: Smoylgt= | C36: =smoylgt -> 63.333333 | F36: zone → | G36: =IF(AND(OR(zoneclim="H2d",zoneclim="H3"),climatisé="OUI"),0,1) | H36: =IF(AND(OR(zoneclim="H2d",zoneclim="H3"),climatisé="OUI"),1,0) | I36: 1
B37: Zone= | C37: =zoneclim -> H1a | G37: =IF(G35*G36,"ICI",FALSE) -> ICI | H37: =IF(H35*H36,"ICI",FALSE) -> FALSE | I37: =IF(I35*I36,"ICI",FALSE) -> FALSE
E38: Smoylgt <= 20 m² | F38: =IF(smoylgt<=20,"ICI",FALSE) -> FALSE | G38: 1250 | H38: 1600 | I38: 2600
E39: 20 < Smoylgt <= 60 | F39: =IF(AND(smoylgt>20,smoylgt<=60),"ICI",FALSE) -> FALSE | G39: 1250 | H39: =1700-(5*smoylgt) -> 1383.3333 | I39: =2850-(12.5*smoylgt) -> 2058.3333
E40: Smoylgt > 60 m² | F40: =IF(smoylgt>60,"ICI",FALSE) -> ICI | G40: 1250 | H40: 1400 | I40: 2100
B42: =IF(usage=B43,"↓↓↓","") | C42: =IF(usage=B43,"↓↓↓","") | G42: Cat 1 sauf clim H2d et H3 | H42: Cat 1 climatisé H2d H3 | I42: Cat 2 | J42: Cat 3
B43: =B5 -> Bureaux | C43: =HLOOKUP("ICI",G46:J47,2,FALSE) -> 1150 | F43: catégorie → | G43: =IF(categorie=G31,1,0) -> 1 | H43: =IF(categorie=G31,1,0) -> 1 | I43: =IF(categorie=H31,1,0) -> 0 | J43: =IF(categorie="Catégorie 3",1,0) -> 0
B44: climatisé= | C44: =climatisé -> NON | F44: climatisé → | G44: =IF(climatisé="OUI",0,1) -> 1 | H44: =IF(climatisé="OUI",1,0) -> 0 | I44: =IF(climatisé="OUI",1,0) -> 0 | J44: 1
...

Sheet Calcul_energie
B2: Mc pour l’énergie
E3: Cepnrmaxmoyen | F3: Cepmaxmoyen | J3: ↓ date PC adaptée ↓ | K3: ↓ usage adaptée ↓ | L3: Icénergie
B4: Les coefficients de modulation des Cep Cepnr et Icénergie commencent tous par « Mc ». Les formules sont : | D4: ↓ usage détaillé ↓ | E4: =VLOOKUP(D5,D6:E33,2,FALSE) -> 70 | F4: =VLOOKUP(D5,D6:F33,3,FALSE) -> 85 | J4: =IF(AND(rcu="OUI",rcu_classe="OUI",OR(depotpc="2022 à 2024",depotpc="2025 à 2027")),L5,IF(OR(depotpc="2028 à 2030",depotpc="à partir de 2031"),N5,depotpc)) | K4: =IF(rcu="OUI",D5&" - RCU",D5&" - autres cas") -> Logement_collectif - autres cas | L4: =INDEX(L6:N61,MATCH(K4,K6:K61,0),MATCH(J4,L5:N5,0)) -> 260
D5: =IF(OR(usage = Enumération!C7,usage = Enumération!C10, usage = Enumération!C12, usage = Enumération!C16,usage = Enumération!C18,usage = Enumération!C20),usage&" - "&usage_secondaire,usage) -> Logement_collectif | E5: Cepnrmaxmoyen | F5: Cepmaxmoyen | I5: Mccat | L5: =Calcul_matiere!E4 -> 2022 à 2024 | M5: =Calcul_matiere!F4 -> 2025 à 2027 | N5: à partir de 2028
B6: Cep,nr_max = Cep,nr_maxmoyen × (1 + Mcgéo + Mccombles + Mcsurf_moy + Mcsurf_tot + Mccat + McHSP) | D6: =Enumération!C4 -> Maisons_individuelles_ou_accolées | E6: 55 | F6: 75 | G6: 0 | H6: 0 | I6: 0 | J6: 6 | K6: {=INDIRECT(ADDRESS(J6,4))&" - RCU"} -> Maisons_individuelles_ou_accolées - RCU | L6: 200 | M6: 200 | N6: 160
D7: =Enumération!C5 -> Logement_collectif | E7: 70 | F7: 85 | G7: 3 | H7: 2 | I7: 2 | J7: =J6+0 -> 6 | K7: {=INDIRECT(ADDRESS(J7,4))&" - autres cas"} -> Maisons_individuelles_ou_accolées - autres cas | L7: 160 | M7: 160 | N7: 160
B8: Cep_max = Cep_maxmoyen × (1 + Mcgéo + Mccombles + Mcsurf_moy + Mcsurf_tot + Mccat + McHSP) | D8: =Enumération!C6 -> Bureaux | E8: 75 | F8: 85 | G8: 6 | H8: 4 | I8: 4 | J8: =J7+1 -> 7 | K8: {=INDIRECT(ADDRESS(J8,4))&" - RCU"} -> Logement_collectif - RCU | L8: 560 | M8: 320 | N8: 260
D9: =_xlfn.CONCAT(Enumération!C$7," - ",Enumération!F4) -> Enseignement_primaire_ou_secondaire - Enseignement primaire | E9: 65 | F9: 72 | G9: 9 | H9: 6 | I9: 7 | J9: =J8+0 -> 7 | K9: {=INDIRECT(ADDRESS(J9,4))&" - autres cas"} -> Logement_collectif - autres cas | L9: 560 | M9: 260 | N9: 260
B10: Icénergie_max = Icénergie_maxmoyen× (1 + Mcgéo + Mccombles + Mcsurf_moy + Mcsurf_tot + Mccat + McHSP) | D10: =_xlfn.CONCAT(Enumération!C$7," - ",Enumération!F5) -> Enseignement_primaire_ou_secondaire - Enseignement secondaire | E10: 63 | F10: 72 | G10: 9 | H10: 8 | I10: 7 | J10: =J9+1 -> 8 | K10: {=INDIRECT(ADDRESS(J10,4))&" - RCU"} -> Bureaux - RCU | L10: 280 | M10: 200 | N10: 200
D11: =Enumération!C8 -> Médiathèques_et_bibliothèques | E11: 93 | F11: 105 | G11: 12 | H11: 10 | I11: 9 | J11: =J10+0 -> 8 | K11: {=INDIRECT(ADDRESS(J11,4))&" - autres cas"} -> Bureaux - autres cas | L11: 200 | M11: 200 | N11: 200
B12: Cep,nr_maxmoyen, Cep_maxmoyen, Icénergie_maxmoyen : valeurs respectives de l’exigence pour un bâtiment moyen, dépendant de l’usage du bâtiment ou de la partie de bâtiment ; | D12: =Enumération!C9 -> Bâtiments_universitaires_d'enseignement_et_de_recherche_et_bâtiments_d’enseignements_atypiques | E12: 102 | F12: 112 | G12: 15 | H12: 12 | I12: 12 | J12: =J11+1 -> 9 | K12: {=INDIRECT(ADDRESS(J12,4))&" - RCU"} -> Enseignement_primaire_ou_secondaire - Enseignement primaire - RCU | L12: 240 | M12: 200 | N12: 140
B13: Mcgéo : coefficient de modulation selon la localisation géographique ; | D13: =_xlfn.CONCAT(Enumération!C$10," - ",Enumération!G4) -> Hôtels - 0, 1 et 2 étoiles (partie nuit) | E13: 121 | F13: 144 | G13: 18 | H13: 14 | I13: 15 | J13: =J12+0 -> 9 | K13: {=INDIRECT(ADDRESS(J13,4))&" - autres cas"} -> Enseignement_primaire_ou_secondaire - Enseignement primaire - autres cas | L13: 240 | M13: 140 | N13: 140
B14: Mccombles : coefficient de modulation selon la surface de plancher de combles aménagés ; | D14: =_xlfn.CONCAT(Enumération!C$10," - ",Enumération!G5) -> Hôtels - 3, 4 et 5 étoiles (partie nuit) | E14: 118 | F14: 138 | G14: 21 | H14: 14 | I14: 15 | J14: =J13+1 -> 10 | K14: {=INDIRECT(ADDRESS(J14,4))&" - RCU"} -> Enseignement_primaire_ou_secondaire - Enseignement secondaire - RCU | L14: 240 | M14: 200 | N14: 140
B15: Mcsurf_moy : coefficient de modulation selon la surface moyenne des logements ; | D15: =_xlfn.CONCAT(Enumération!C$10," - ",Enumération!G6) -> Hôtels - 0, 1 et 2 étoiles (partie jour) | E15: 235 | F15: 252 | G15: 24 | H15: 14 | I15: 15 | J15: =J14+0 -> 10 | K15: {=INDIRECT(ADDRESS(J15,4))&" - autres cas"} -> Enseignement_primaire_ou_secondaire - Enseignement secondaire - autres cas | L15: 240 | M15: 140 | N15: 140
B16: Mcsurf_tot : coefficient de modulation selon la surface de référence ; | D16: =_xlfn.CONCAT(Enumération!C$10," - ",Enumération!G7) -> Hôtels - 3, 4 et 5 étoiles (partie jour) | E16: 234 | F16: 281 | G16: 27 | H16: 14 | I16: 15 | J16: =J15+1 -> 11 | K16: {=INDIRECT(ADDRESS(J16,4))&" - RCU"} -> Médiathèques_et_bibliothèques - RCU | L16: 360 | M16: 285 | N16: 285
B17: Mccat : coefficient de modulation selon la catégorie de contraintes extérieures. | D17: =Enumération!C11 -> Etablissements_d'accueil_de_la_petite_enfance | E17: 150 | F17: 182 | G17: 30 | H17: 16 | I17: 18 | J17: =J16+0 -> 11 | K17: {=INDIRECT(ADDRESS(J17,4))&" - autres cas"} -> Médiathèques_et_bibliothèques - autres cas | L17: - | M17: 285 | N17: 285
B18: McHSP : coefficient de modulation selon la hauteur sous plafond moyenne des étages. | D18: =_xlfn.CONCAT(Enumération!C$12," - ",Enumération!H4) -> Restaurants - en continu, 18 heures par jour, 7 jours sur 7 | E18: 282 | F18: 578 | G18: 33 | H18: 18 | I18: 21 | J18: =J17+1 -> 12 | K18: {=INDIRECT(ADDRESS(J18,4))&" - RCU"} -> Bâtiments_universitaires_d'enseignement_et_de_recherche_et_bâtiments_d’enseignements_atypiques - RCU | L18: 225 | M18: 190 | N18: 190
D19: =_xlfn.CONCAT(Enumération!C$12," - ",Enumération!H5) -> Restaurants - 1 repas par jour, 5 jours sur 7 | E19: 132 | F19: 275 | G19: 36 | H19: 18 | I19: 21 | J19: =J18+0 -> 12 | K19: {=INDIRECT(ADDRESS(J19,4))&" - autres cas"} -> Bâtiments_universitaires_d'enseignement_et_de_recherche_et_bâtiments_d’enseignements_atypiques - autres cas | L19: - | M19: 190 | N19: 190
D20: =_xlfn.CONCAT(Enumération!C$12," - ",Enumération!H6) -> Restaurants - 2 repas par jour, 7 jours sur 7 | E20: 219 | F20: 446 | G20: 39 | H20: 18 | I20: 21 | J20: =J19+1 -> 13 | K20: {=INDIRECT(ADDRESS(J20,4))&" - RCU"} -> Hôtels - 0, 1 et 2 étoiles (partie nuit) - RCU | L20: 490 | M20: 390 | N20: 390
D21: =_xlfn.CONCAT(Enumération!C$12," - ",Enumération!H7) -> Restaurants - 2 repas par jour, 6 jours sur 7 | E21: 214 | F21: 412 | G21: 42 | H21: 18 | I21: 21 | J21: =J20+0 -> 13 | K21: {=INDIRECT(ADDRESS(J21,4))&" - autres cas"} -> Hôtels - 0, 1 et 2 étoiles (partie nuit) - autres cas | L21: - | M21: 390 | N21: 390
D22: =Enumération!C13 -> Commerces | E22: 163 | F22: 182 | G22: 45 | H22: 20 | I22: 24 | J22: =J21+1 -> 14 | K22: {=INDIRECT(ADDRESS(J22,4))&" - RCU"} -> Hôtels - 3, 4 et 5 étoiles (partie nuit) - RCU | L22: 485 | M22: 350 | N22: 350
D23: =Enumération!C14 -> Vestiaires seuls | E23: 242 | F23: 306 | G23: 48 | H23: 22 | I23: 27 | J23: =J22+0 -> 14 | K23: {=INDIRECT(ADDRESS(J23,4))&" - autres cas"} -> Hôtels - 3, 4 et 5 étoiles (partie nuit) - autres cas | L23: - | M23: 350 | N23: 350
D24: =Enumération!C15 -> Etablissements_sanitaires_avec_hébergement | E24: 190 | F24: 252 | G24: 51 | H24: 24 | I24: 30 | J24: =J23+1 -> 15 | K24: {=INDIRECT(ADDRESS(J24,4))&" - RCU"} -> Hôtels - 0, 1 et 2 étoiles (partie jour) - RCU | L24: 595 | M24: 495 | N24: 495
D25: =_xlfn.CONCAT(Enumération!C$16," - ",Enumération!I4) -> Etablissements_de_santé - partie nuit | E25: 274 | F25: 302 | G25: 54 | H25: 26 | I25: 33 | J25: =J24+0 -> 15 | K25: {=INDIRECT(ADDRESS(J25,4))&" - autres cas"} -> Hôtels - 0, 1 et 2 étoiles (partie jour) - autres cas | L25: - | M25: 495 | N25: 495
D26: =_xlfn.CONCAT(Enumération!C$16," - ",Enumération!I5) -> Etablissements_de_santé - partie jour | E26: 165 | F26: 180 | G26: 57 | H26: 26 | I26: 33 | J26: =J25+1 -> 16 | K26: {=INDIRECT(ADDRESS(J26,4))&" - RCU"} -> Hôtels - 3, 4 et 5 étoiles (partie jour) - RCU | L26: 630 | M26: 520 | N26: 520
D27: =Enumération!C17 -> Aérogares | E27: 191 | F27: 253 | G27: 60 | H27: 28 | I27: 36 | J27: =J26+0 -> 16 | K27: {=INDIRECT(ADDRESS(J27,4))&" - autres cas"} -> Hôtels - 3, 4 et 5 étoiles (partie jour) - autres cas | L27: - | M27: 520 | N27: 520
D28: =_xlfn.CONCAT(Enumération!C$18," - ",Enumération!J4) -> Industries_ou_artisanats - 3x8h | E28: 290 | F28: 365 | G28: 63 | H28: 30 | I28: 39 | J28: =J27+1 -> 17 | K28: {=INDIRECT(ADDRESS(J28,4))&" - RCU"} -> Etablissements_d'accueil_de_la_petite_enfance - RCU | L28: 895 | M28: 680 | N28: 680
D29: =_xlfn.CONCAT(Enumération!C$18," - ",Enumération!J5) -> Industries_ou_artisanats - 8h à 18h | E29: 94 | F29: 116 | G29: 66 | H29: 30 | I29: 39 | J29: =J28+0 -> 17 | K29: {=INDIRECT(ADDRESS(J29,4))&" - autres cas"} -> Etablissements_d'accueil_de_la_petite_enfance - autres cas | L29: - | M29: 680 | N29: 680
D30: =Enumération!C19 -> Etablissements_sportifs_municipaux_ou_scolaires | E30: 94 | F30: 116 | G30: 69 | H30: 32 | I30: 42 | J30: =J29+1 -> 18 | K30: {=INDIRECT(ADDRESS(J30,4))&" - RCU"} -> Restaurants - en continu, 18 heures par jour, 7 jours sur 7 - RCU | L30: 670 | M30: 570 | N30: 570
D31: =_xlfn.CONCAT(Enumération!C$20," - ",Enumération!K4) -> Restaurants_scolaires - 1 repas par jour, 5 jours sur 7 | E31: 119 | F31: 251 | G31: 72 | H31: 34 | I31: 45 | J31: =J30+0 -> 18 | K31: {=INDIRECT(ADDRESS(J31,4))&" - autres cas"} -> Restaurants - en continu, 18 heures par jour, 7 jours sur 7 - autres cas | L31: - | M31: 570 | N31: 570
D32: =_xlfn.CONCAT(Enumération!C$20," - ",Enumération!K5) -> Restaurants_scolaires - 3 repas par jour, 5 jours sur 7 | E32: 153 | F32: 329 | G32: 75 | H32: 34 | I32: 45 | J32: =J31+1 -> 19 | K32: {=INDIRECT(ADDRESS(J32,4))&" - RCU"} -> Restaurants - 1 repas par jour, 5 jours sur 7 - RCU | L32: 605 | M32: 470 | N32: 470
D33: =Enumération!C21 -> Etablissements_sportifs_privés | E33: 112 | F33: 148 | G33: 78 | H33: 36 | I33: 48 | J33: =J32+0 -> 19 | K33: {=INDIRECT(ADDRESS(J33,4))&" - autres cas"} -> Restaurants - 1 repas par jour, 5 jours sur 7 - autres cas | L33: - | M33: 470 | N33: 470
J34: =J33+1 -> 20 | K34: {=INDIRECT(ADDRESS(J34,4))&" - RCU"} -> Restaurants - 2 repas par jour, 7 jours sur 7 - RCU | L34: 705 | M34: 570 | N34: 570
J35: =J34+0 -> 20 | K35: {=INDIRECT(ADDRESS(J35,4))&" - autres cas"} -> Restaurants - 2 repas par jour, 7 jours sur 7 - autres cas | L35: - | M35: 570 | N35: 570
J36: =J35+1 -> 21 | K36: {=INDIRECT(ADDRESS(J36,4))&" - RCU"} -> Restaurants - 2 repas par jour, 6 jours sur 7 - RCU | L36: 675 | M36: 545 | N36: 545
J37: =J36+0 -> 21 | K37: {=INDIRECT(ADDRESS(J37,4))&" - autres cas"} -> Restaurants - 2 repas par jour, 6 jours sur 7 - autres cas | L37: - | M37: 545 | N37: 545
J38: =J37+1 -> 22 | K38: {=INDIRECT(ADDRESS(J38,4))&" - RCU"} -> Commerces - RCU | L38: 315 | M38: 315 | N38: 315
J39: =J38+0 -> 22 | K39: {=INDIRECT(ADDRESS(J39,4))&" - autres cas"} -> Commerces - autres cas | L39: - | M39: 315 | N39: 315
J40: =J39+1 -> 23 | K40: {=INDIRECT(ADDRESS(J40,4))&" - RCU"} -> Vestiaires seuls - RCU | L40: 1460 | M40: 1120 | N40: 1120
J41: =J40+0 -> 23 | K41: {=INDIRECT(ADDRESS(J41,4))&" - autres cas"} -> Vestiaires seuls - autres cas | L41: - | M41: 585 | N41: 585
...

Sheet Calcul_bbio
B2: Mb pour le BBIO
D3: ↓ usage détaillé ↓ | E3: Bbiomaxmoyen
B4: Les coefficients de modulation du BBIO commencent tous par « Mb ». La formule du Bbio_max est : | D4: =usage_detaillé -> Logement_collectif | E4: =VLOOKUP(D4,D5:E32,2,FALSE) -> 65
D5: =Enumération!C4 -> Maisons_individuelles_ou_accolées | E5: 63 | F5: 0 | G5: 0 | H5: =IF(OR(usage=D4,usage=D5),"logement","") -> logement
B6: Bbio_max = Bbio_maxmoyen × (1 + Mbgéo + Mbcombles + Mbsurf_moy + Mbsurf_tot + Mbbruit + MbHSP) | D6: =Enumération!C5 -> Logement_collectif | E6: 65 | F6: 3 | G6: 2
D7: =Enumération!C6 -> Bureaux | E7: 95 | F7: 6 | G7: 4
B8: Bbio_maxmoyen : valeur de l’exigence Bbio_max pour un bâtiment moyen, dépendant de l’usage du bâtiment ou de la partie de bâtiment ; | D8: =_xlfn.CONCAT(Enumération!C$7," - ",Enumération!F4) -> Enseignement_primaire_ou_secondaire - Enseignement primaire | E8: 68 | F8: 9 | G8: 7
B9: Mbgéo : coefficient de modulation selon la localisation géographique | D9: =_xlfn.CONCAT(Enumération!C$7," - ",Enumération!F5) -> Enseignement_primaire_ou_secondaire - Enseignement secondaire | E9: =E8 -> 68 | F9: 9
B10: Mbcombles : coefficient de modulation selon la surface de plancher de combles aménagés du bâtiment ou de la partie de bâtiment, pour les maisons individuelles ; | D10: =Enumération!C8 -> Médiathèques_et_bibliothèques | E10: 117 | F10: 12
B11: Mbsurf_moy : coefficient de modulation selon la surface moyenne des logements ; | D11: =Enumération!C9 -> Bâtiments_universitaires_d'enseignement_et_de_recherche_et_bâtiments_d’enseignements_atypiques | E11: 122 | F11: 15
B12: Mbsurf_tot : coefficient de modulation selon la surface de référence ; | D12: =_xlfn.CONCAT(Enumération!C$10," - ",Enumération!G4) -> Hôtels - 0, 1 et 2 étoiles (partie nuit) | E12: 76 | F12: 18
B13: Mbbruit : coefficient de modulation selon l’exposition au bruit des infrastructures de transport à proximité du bâtiment. | D13: =_xlfn.CONCAT(Enumération!C$10," - ",Enumération!G5) -> Hôtels - 3, 4 et 5 étoiles (partie nuit) | E13: 76 | F13: 21
B14: MbHSP : coefficient de modulation selon la hauteur sous plafond moyenne des étages. | D14: =_xlfn.CONCAT(Enumération!C$10," - ",Enumération!G6) -> Hôtels - 0, 1 et 2 étoiles (partie jour) | E14: 134 | F14: 24
D15: =_xlfn.CONCAT(Enumération!C$10," - ",Enumération!G7) -> Hôtels - 3, 4 et 5 étoiles (partie jour) | E15: 163 | F15: 27
D16: =Enumération!C11 -> Etablissements_d'accueil_de_la_petite_enfance | E16: 139 | F16: 30
D17: =_xlfn.CONCAT(Enumération!C$12," - ",Enumération!H4) -> Restaurants - en continu, 18 heures par jour, 7 jours sur 7 | E17: 245 | F17: 33
D18: =_xlfn.CONCAT(Enumération!C$12," - ",Enumération!H5) -> Restaurants - 1 repas par jour, 5 jours sur 7 | E18: 100 | F18: 36
D19: =_xlfn.CONCAT(Enumération!C$12," - ",Enumération!H6) -> Restaurants - 2 repas par jour, 7 jours sur 7 | E19: 206 | F19: 39
D20: =_xlfn.CONCAT(Enumération!C$12," - ",Enumération!H7) -> Restaurants - 2 repas par jour, 6 jours sur 7 | E20: 177 | F20: 42
D21: =Enumération!C13 -> Commerces | E21: 170 | F21: 45
D22: =Enumération!C14 -> Vestiaires seuls | E22: 225 | F22: 48
D23: =Enumération!C15 -> Etablissements_sanitaires_avec_hébergement | E23: 174 | F23: 51
D24: =_xlfn.CONCAT(Enumération!C$16," - ",Enumération!I4) -> Etablissements_de_santé - partie nuit | E24: 164 | F24: 54
D25: =_xlfn.CONCAT(Enumération!C$16," - ",Enumération!I5) -> Etablissements_de_santé - partie jour | E25: 133 | F25: 57
D26: =Enumération!C17 -> Aérogares | E26: 248 | F26: 60
D27: =_xlfn.CONCAT(Enumération!C$18," - ",Enumération!J4) -> Industries_ou_artisanats - 3x8h | E27: 257 | F27: 63
D28: =_xlfn.CONCAT(Enumération!C$18," - ",Enumération!J5) -> Industries_ou_artisanats - 8h à 18h | E28: 69 | F28: 66
D29: =Enumération!C19 -> Etablissements_sportifs_municipaux_ou_scolaires | E29: 94 | F29: 69
D30: =_xlfn.CONCAT(Enumération!C$20," - ",Enumération!K4) -> Restaurants_scolaires - 1 repas par jour, 5 jours sur 7 | E30: 76 | F30: 72
D31: =_xlfn.CONCAT(Enumération!C$20," - ",Enumération!K5) -> Restaurants_scolaires - 3 repas par jour, 5 jours sur 7 | E31: 116 | F31: 75
D32: =Enumération!C21 -> Etablissements_sportifs_privés | E32: =E29 -> 94 | F32: 78
D34: Mbgeo | E34: {=INDEX(E37:CG44,MATCH(zoneclim,D37:D44,0),MATCH(elevation,E36:G36,0)+D36)} -> 0.1
E35: =Enumération!C39 -> Maisons_individuelles_ou_accolées | H35: =Enumération!F39 -> Logement_collectif | K35: =Enumération!I39 -> Bureaux | N35: =Enumération!L39 -> Enseignement_primaire_ou_secondaire | Q35: =Enumération!O39 -> Médiathèques_et_bibliothèques | T35: =Enumération!R39 -> Bâtiments_universitaires_d'enseignement_et_de_recherche_et_bâtiments_d’enseignements_atypiques | W35: Hôtels - 0, 1 et 2 étoiles (partie nuit) | Z35: Hôtels - 3, 4 et 5 étoiles (partie nuit) | AC35: Hôtels - 0, 1 et 2 étoiles (partie jour) | AF35: Hôtels - 3, 4 et 5 étoiles (partie jour) | AI35: =Enumération!X39 -> Etablissements_d'accueil_de_la_petite_enfance | AL35: Restaurants - en continu, 18 heures par jour, 7 jours sur 7 | AO35: Restaurants - 1 repas par jour, 5 jours sur 7 | AR35: Restaurants - 2 repas par jour, 7 jours sur 7 | AU35: Restaurants - 2 repas par jour, 6 jours sur 7 | AX35: =Enumération!AD39 -> Commerces | BA35: =Enumération!AG39 -> Vestiaires seuls | BD35: =Enumération!AJ39 -> Etablissements_sanitaires_avec_hébergement | BG35: Etablissements_de_santé - partie nuit | BJ35: Etablissements_de_santé - partie jour | BM35: =Enumération!AP39 -> Aérogares | BP35: Industries_ou_artisanats - 3x8h | BS35: Industries_ou_artisanats - 8h à 18h | BV35: =Enumération!AV39 -> Etablissements_sportifs_municipaux_ou_scolaires | BY35: Restaurants_scolaires - 1 repas par jour, 5 jours sur 7 | CB35: Restaurants_scolaires - 3 repas par jour, 5 jours sur 7 | CE35: =Enumération!BB39 -> Etablissements_sportifs_privés
D36: =VLOOKUP(D4,Calcul_bbio!D5:F32,3,FALSE) -> 3 | E36: <400m | F36: 400m-800m | G36: >800m | H36: =E36 -> <400m | I36: =F36 -> 400m-800m | J36: =G36 -> >800m | K36: =H36 -> <400m | L36: =I36 -> 400m-800m | M36: =J36 -> >800m | N36: =K36 -> <400m | O36: =L36 -> 400m-800m | ... CG36: =CD36 -> >800m
D37: H1a | E37: 0.15 | F37: 0.4 | G37: 0.75 | H37: 0.1 | I37: 0.4 | J37: 0.8 | K37: 0.05 | L37: 0.25 | M37: 0.45 | N37: 0.1 | O37: 0.25 | P37: 0.45 | Q37: 0.05 | R37: 0.2 | S37: 0.4 | T37: 0.1 | U37: 0.3 | V37: 0.5 | W37: 0.15 | X37: 0.45 | Y37: 0.75 | Z37: 0.15 | AA37: 0.45 | AB37: 0.75 | AC37: 0.1 | AD37: 0.25 | AE37: 0.45 | AF37: 0.05 | AG37: 0.25 | AH37: 0.45 | AI37: 0.1 | AJ37: 0.25 | AK37: 0.45 | AL37: 0.05 | AM37: 0.15 | AN37: 0.3 | AO37: 0.1 | AP37: 0.3 | AQ37: 0.55 | AR37: 0.05 | AS37: 0.2 | AT37: 0.35 | AU37: 0.05 | AV37: 0.2 | AW37: 0.35 | AX37: 0.05 | AY37: 0.1 | AZ37: 0.2 | BA37: 0.05 | BB37: 0.3 | BC37: 0.55 | BD37: 0.1 | BE37: 0.25 | BF37: 0.45 | BG37: 0.05 | BH37: 0.25 | BI37: 0.45 | BJ37: 0.05 | BK37: 0.15 | BL37: 0.25 | BM37: 0.05 | BN37: 0.1 | BO37: 0.05 | BP37: 0.05 | BQ37: 0.05 | BR37: 0.1 | BS37: 0.1 | BT37: 0.2 | BU37: 0.35 | BV37: 0 | BW37: 0 | BX37: 0.05 | BY37: 0.15 | BZ37: 0.35 | CA37: 0.65 | CB37: 0.1 | CC37: 0.3 | CD37: 0.55 | CE37: 0 | CF37: 0 | CG37: 0.05
D38: H1b | E38: 0.2 | F38: 0.5 | G38: 0.85 | H38: 0.2 | I38: 0.5 | J38: 0.85 | K38: 0.1 | L38: 0.25 | M38: 0.45 | N38: 0.2 | O38: 0.3 | P38: 0.45 | Q38: 0.2 | R38: 0.3 | S38: 0.5 | T38: 0.2 | U38: 0.35 | V38: 0.6 | W38: 0.2 | X38: 0.45 | Y38: 0.8 | Z38: 0.2 | AA38: 0.45 | AB38: 0.75 | AC38: 0.15 | AD38: 0.3 | AE38: 0.55 | AF38: 0.15 | AG38: 0.3 | AH38: 0.5 | AI38: 0.15 | AJ38: 0.3 | AK38: 0.5 | AL38: 0.1 | AM38: 0.2 | AN38: 0.35 | AO38: 0.15 | AP38: 0.35 | AQ38: 0.55 | AR38: 0.1 | AS38: 0.25 | AT38: 0.4 | AU38: 0.15 | AV38: 0.25 | AW38: 0.4 | AX38: 0.1 | AY38: 0.2 | AZ38: 0.3 | BA38: 0.1 | BB38: 0.3 | BC38: 0.55 | BD38: 0.15 | BE38: 0.3 | BF38: 0.5 | BG38: 0.15 | BH38: 0.3 | BI38: 0.5 | BJ38: 0.15 | BK38: 0.2 | BL38: 0.3 | BM38: 0.1 | BN38: 0.15 | BO38: 0.15 | BP38: 0.05 | BQ38: 0.1 | BR38: 0.15 | BS38: 0.15 | BT38: 0.25 | BU38: 0.4 | BV38: 0.1 | BW38: 0.05 | BX38: 0.1 | BY38: 0.2 | BZ38: 0.4 | CA38: 0.65 | CB38: 0.15 | CC38: 0.35 | CD38: 0.55 | CE38: 0.1 | CF38: 0.05 | CG38: 0.1
D39: H1c | E39: 0.2 | F39: 0.45 | G39: 0.75 | H39: 0.15 | I39: 0.45 | J39: 0.75 | K39: 0.2 | L39: 0.2 | M39: 0.4 | N39: 0.25 | O39: 0.25 | P39: 0.4 | Q39: 0.25 | R39: 0.3 | S39: 0.4 | T39: 0.2 | U39: 0.35 | V39: 0.5 | W39: 0.2 | X39: 0.4 | Y39: 0.7 | Z39: 0.2 | AA39: 0.4 | AB39: 0.65 | AC39: 0.25 | AD39: 0.35 | AE39: 0.5 | AF39: 0.2 | AG39: 0.3 | AH39: 0.45 | AI39: 0.1 | AJ39: 0.25 | AK39: 0.4 | AL39: 0.2 | AM39: 0.25 | AN39: 0.35 | AO39: 0.2 | AP39: 0.3 | AQ39: 0.5 | AR39: 0.15 | AS39: 0.25 | AT39: 0.35 | AU39: 0.15 | AV39: 0.25 | AW39: 0.35 | AX39: 0.15 | AY39: 0.2 | AZ39: 0.25 | BA39: 0.1 | BB39: 0.25 | BC39: 0.5 | BD39: 0.15 | BE39: 0.25 | BF39: 0.45 | BG39: 0.2 | BH39: 0.3 | BI39: 0.45 | BJ39: 0.2 | BK39: 0.2 | BL39: 0.25 | BM39: 0.15 | BN39: 0.2 | BO39: -0.05 | BP39: 0.1 | BQ39: 0.1 | BR39: 0.15 | BS39: 0.25 | BT39: 0.3 | BU39: 0.45 | BV39: 0.25 | BW39: 0.15 | BX39: 0.15 | BY39: 0.15 | BZ39: 0.35 | CA39: 0.6 | CB39: 0.15 | CC39: 0.3 | CD39: 0.5 | CE39: 0.25 | CF39: 0.15 | CG39: 0.15
D40: H2a | E40: -0.05 | F40: 0.15 | G40: 0.55 | H40: -0.1 | I40: 0.2 | J40: 0.6 | K40: -0.05 | L40: 0.2 | M40: 0.4 | N40: -0.1 | O40: 0.05 | P40: 0.3 | Q40: -0.1 | R40: 0 | S40: 0.15 | T40: -0.05 | U40: 0.1 | V40: 0.3 | W40: 0 | X40: 0.25 | Y40: 0.6 | Z40: 0 | AA40: 0.25 | AB40: 0.6 | AC40: -0.1 | AD40: 0.05 | AE40: 0.3 | AF40: -0.1 | AG40: 0.1 | AH40: 0.3 | AI40: 0 | AJ40: 0.15 | AK40: 0.4 | AL40: -0.05 | AM40: 0.05 | AN40: 0.2 | AO40: 0 | AP40: 0.2 | AQ40: 0.45 | AR40: -0.05 | AS40: 0.1 | AT40: 0.25 | AU40: -0.05 | AV40: 0.05 | AW40: 0.25 | AX40: -0.05 | AY40: 0 | AZ40: 0.15 | BA40: -0.05 | BB40: 0.2 | BC40: 0.45 | BD40: -0.05 | BE40: 0.15 | BF40: 0.3 | BG40: -0.05 | BH40: 0.15 | BI40: 0.35 | BJ40: -0.05 | BK40: 0.05 | BL40: 0.15 | BM40: -0.05 | BN40: 0 | BO40: 0 | BP40: -0.05 | BQ40: 0 | BR40: 0.05 | BS40: -0.05 | BT40: 0.05 | BU40: 0.2 | BV40: -0.15 | BW40: -0.15 | BX40: -0.05 | BY40: -0.05 | BZ40: 0.2 | CA40: 0.5 | CB40: -0.05 | CC40: 0.15 | CD40: 0.45 | CE40: -0.15 | CF40: -0.15 | CG40: -0.05
D41: H2b | E41: 0 | F41: 0.3 | G41: 0.65 | H41: 0 | I41: 0.3 | J41: 0.65 | K41: 0 | L41: 0.2 | M41: 0.35 | N41: 0 | O41: 0.1 | P41: 0.35 | Q41: 0 | R41: 0.1 | S41: 0.3 | T41: 0 | U41: 0.2 | V41: 0.4 | W41: 0 | X41: 0.3 | Y41: 0.6 | Z41: 0 | AA41: 0.3 | AB41: 0.6 | AC41: 0 | AD41: 0.15 | AE41: 0.35 | AF41: 0 | AG41: 0.15 | AH41: 0.35 | AI41: 0 | AJ41: 0.2 | AK41: 0.4 | AL41: 0 | AM41: 0.1 | AN41: 0.25 | AO41: 0 | AP41: 0.2 | AQ41: 0.45 | AR41: 0 | AS41: 0.15 | AT41: 0.3 | AU41: 0 | AV41: 0.15 | AW41: 0.3 | AX41: 0 | AY41: 0.1 | AZ41: 0.2 | BA41: 0 | BB41: 0.25 | BC41: 0.5 | BD41: 0 | BE41: 0.15 | BF41: 0.35 | BG41: 0 | BH41: 0.2 | BI41: 0.4 | BJ41: 0 | BK41: 0.05 | BL41: 0.2 | BM41: 0 | BN41: 0.1 | BO41: 0.1 | BP41: 0 | BQ41: 0.05 | BR41: 0.1 | BS41: 0 | BT41: 0.1 | BU41: 0.25 | BV41: 0 | BW41: -0.05 | BX41: 0 | BY41: 0 | BZ41: 0.25 | CA41: 0.55 | CB41: 0 | CC41: 0.2 | CD41: 0.45 | CE41: 0 | CF41: -0.05 | CG41: 0
D42: H2c | E42: -0.1 | F42: 0.05 | G42: 0.35 | H42: -0.1 | I42: 0.1 | J42: 0.4 | K42: 0.1 | L42: 0.1 | M42: 0.25 | N42: 0.05 | O42: 0 | P42: 0.2 | Q42: 0 | R42: 0 | S42: 0.1 | T42: 0 | U42: 0.05 | V42: 0.2 | W42: -0.1 | X42: 0.15 | Y42: 0.4 | Z42: -0.1 | AA42: 0.15 | AB42: 0.4 | AC42: 0 | AD42: 0.05 | AE42: 0.2 | AF42: -0.05 | AG42: 0.05 | AH42: 0.2 | AI42: -0.1 | AJ42: 0.05 | AK42: 0.25 | AL42: 0.05 | AM42: 0.05 | AN42: 0.15 | AO42: -0.05 | AP42: 0.05 | AQ42: 0.25 | AR42: 0 | AS42: 0.05 | AT42: 0.15 | AU42: 0 | AV42: 0.05 | AW42: 0.15 | AX42: 0.05 | AY42: 0 | AZ42: 0.1 | BA42: -0.1 | BB42: 0.05 | BC42: 0.3 | BD42: -0.05 | BE42: 0.1 | BF42: 0.25 | BG42: 0 | BH42: 0.1 | BI42: 0.25 | BJ42: 0 | BK42: 0 | BL42: 0.1 | BM42: 0.05 | BN42: 0.05 | BO42: 0.25 | BP42: 0.05 | BQ42: 0.05 | BR42: 0.05 | BS42: 0.05 | BT42: 0.05 | BU42: 0.15 | BV42: 0.1 | BW42: -0.05 | BX42: -0.05 | BY42: -0.05 | BZ42: 0.1 | CA42: 0.35 | CB42: -0.05 | CC42: 0.1 | CD42: 0.3 | CE42: 0.1 | CF42: -0.05 | CG42: -0.05
...

Sheet Calcul_matiere
B2: Mi pour l’Icconstruction
D3: Icconstruction_maxmoyen | E3: =INDEX(E5:H22,MATCH(usage,D5:D22,0),MATCH(depotpc,E4:H4,0)) -> 650 | G3: incluant (ou pas) IGH | L3: Base officiel
B4: Les coefficients de modulation de l’ICconstruction commencent tous par « Mi ». La formule du Icconstruction_max est : | E4: 2022 à 2024 | F4: 2025 à 2027 | G4: 2028 à 2030 | H4: à partir de 2031 | L4: 2028 à 2030 | M4: à partir de 2031
D5: =Enumération!C4 -> Maisons_individuelles_ou_accolées | E5: 640 | F5: 530 | G5: =IF(est_igh="OUI",F5*G$23,L5) -> 475 | H5: =IF(est_igh="OUI",L5*$H$23,M5) -> 415 | I5: 0 | J5: 0 | L5: 475 | M5: 415
B6: Icconstruction_max = Icconstruction_maxmoyen × (1 + Micombles + Misurf_moy + Misurf_tot) + Migéo + Miinfra + Mivrd + Mipv + Mided + Miagrément_ext + Mi_HSP + Miclim_RCU | D6: =Enumération!C5 -> Logement_collectif | E6: 740 | F6: 650 | G6: =IF(est_igh="OUI",F6*G$23,L6) -> 580 | H6: =IF(est_igh="OUI",L6*$H$23,M6) -> 490 | I6: 3 | J6: 2 | L6: 580 | M6: 490
D7: =Enumération!C6 -> Bureaux | E7: 980 | F7: 810 | G7: =IF(est_igh="OUI",F7*G$23,L7) -> 710 | H7: =IF(est_igh="OUI",L7*$H$23,M7) -> 600 | I7: 6 | J7: 4 | L7: 710 | M7: 600
B8: Icconstruction_maxmoyen : valeur de l’exigence Icconstruction_max pour un bâtiment moyen, dépendant de l’usage ; | D8: =Enumération!C7 -> Enseignement_primaire_ou_secondaire | E8: 900 | F8: 770 | G8: =IF(est_igh="OUI",F8*G$23,L8) -> 680 | H8: =IF(est_igh="OUI",L8*$H$23,M8) -> 590 | I8: 9 | J8: 7 | L8: 680 | M8: 590
B9: Micombles : coefficient de modulation selon la surface de plancher de combles aménagés pour les maisons individuelles ; | D9: =Enumération!C8 -> Médiathèques_et_bibliothèques | E9: - | F9: 940 | G9: =IF(est_igh="OUI",F9*G$23,L9) -> 785 | H9: =IF(est_igh="OUI",L9*$H$23,M9) -> 630 | I9: =I8+3 -> 12 | L9: 785 | M9: 630
B10: Misurf_moy : coefficient de modulation selon la surface moyenne des logements ; | D10: =Enumération!C9 -> Bâtiments_universitaires_d'enseignement_et_de_recherche_et_bâtiments_d’enseignements_atypiques | E10: - | F10: 940 | G10: =IF(est_igh="OUI",F10*G$23,L10) -> 790 | H10: =IF(est_igh="OUI",L10*$H$23,M10) -> 640 | I10: =I9+3 -> 15 | L10: 790 | M10: 640
B11: Misurf_tot : coefficient de modulation selon la surface de référence | D11: =Enumération!C10 -> Hôtels | E11: - | F11: 820 | G11: =IF(est_igh="OUI",F11*G$23,L11) -> 680 | H11: =IF(est_igh="OUI",L11*$H$23,M11) -> 540 | I11: =I10+3 -> 18 | L11: 680 | M11: 540
B12: Migéo : coefficient de modulation selon la localisation géographique ; | D12: =Enumération!C11 -> Etablissements_d'accueil_de_la_petite_enfance | E12: - | F12: 950 | G12: =IF(est_igh="OUI",F12*G$23,L12) -> 780 | H12: =IF(est_igh="OUI",L12*$H$23,M12) -> 630 | I12: =I11+3 -> 21 | L12: 780 | M12: 630
B13: Miinfra : coefficient de modulation selon l’impact des fondations, des espaces en sous-sol et des parcs de stationnement couverts ; | D13: =Enumération!C12 -> Restaurants | E13: - | F13: 800 | G13: =IF(est_igh="OUI",F13*G$23,L13) -> 670 | H13: =IF(est_igh="OUI",L13*$H$23,M13) -> 540 | I13: =I12+3 -> 24 | L13: 670 | M13: 540
B14: Mivrd : coefficient de modulation selon l’impact de la voirie et des réseaux divers ; | D14: =Enumération!C13 -> Commerces | E14: - | F14: 800 | G14: =IF(est_igh="OUI",F14*G$23,L14) -> 670 | H14: =IF(est_igh="OUI",L14*$H$23,M14) -> 540 | I14: =I13+3 -> 27 | L14: 670 | M14: 540
B15: Mipv : coefficient de modulation selon l’impact de l’installation des panneaux photovoltaïques ; | D15: =Enumération!C14 -> Vestiaires seuls | E15: - | F15: 1050 | G15: =IF(est_igh="OUI",F15*G$23,L15) -> 900 | H15: =IF(est_igh="OUI",L15*$H$23,M15) -> 750 | I15: =I14+3 -> 30 | L15: 900 | M15: 750
B16: Mided : coefficient de modulation selon l’impact des données environnementales par défaut et valeurs forfaitaires. | D16: =Enumération!C15 -> Etablissements_sanitaires_avec_hébergement | E16: - | F16: 880 | G16: =IF(est_igh="OUI",F16*G$23,L16) -> 760 | H16: =IF(est_igh="OUI",L16*$H$23,M16) -> 620 | I16: =I15+3 -> 33 | L16: 760 | M16: 620
B17: Miagrément_ext : coefficient de modulation selon la surface d’agrément extérieur (balcons, loggias) du bâtiment ou de la partie de bâtiment, pour les logements collectifs; | D17: =Enumération!C16 -> Etablissements_de_santé | E17: - | F17: 880 | G17: =IF(est_igh="OUI",F17*G$23,L17) -> 760 | H17: =IF(est_igh="OUI",L17*$H$23,M17) -> 620 | I17: =I16+3 -> 36 | L17: 760 | M17: 620
B18: Mi_HSP : coefficient de modulation selon la hauteur sous plafond moyenne des étages; | D18: =Enumération!C17 -> Aérogares | E18: - | F18: 1120 | G18: =IF(est_igh="OUI",F18*G$23,L18) -> 950 | H18: =IF(est_igh="OUI",L18*$H$23,M18) -> 780 | I18: =I17+3 -> 39 | L18: 950 | M18: 780
B19: Miclim_RCU : coefficient de modulation selon la présence ou non d’un système de climatisation, pour les bâtiments raccordés à un réseau de chaleur urbain classé; | D19: =Enumération!C18 -> Industries_ou_artisanats | E19: - | F19: 840 | G19: =IF(est_igh="OUI",F19*G$23,L19) -> 695 | H19: =IF(est_igh="OUI",L19*$H$23,M19) -> 550 | I19: =I18+3 -> 42 | L19: 695 | M19: 550
D20: =Enumération!C19 -> Etablissements_sportifs_municipaux_ou_scolaires | E20: - | F20: 900 | G20: =IF(est_igh="OUI",F20*G$23,L20) -> 760 | H20: =IF(est_igh="OUI",L20*$H$23,M20) -> 620 | I20: =I19+3 -> 45 | L20: 760 | M20: 620
D21: =Enumération!C20 -> Restaurants_scolaires | E21: - | F21: 800 | G21: =IF(est_igh="OUI",F21*G$23,L21) -> 670 | H21: =IF(est_igh="OUI",L21*$H$23,M21) -> 540 | I21: =I20+3 -> 48 | L21: 670 | M21: 540
D22: =Enumération!C21 -> Etablissements_sportifs_privés | E22: - | F22: 900 | G22: =IF(est_igh="OUI",F22*G$23,L22) -> 760 | H22: =IF(est_igh="OUI",L22*$H$23,M22) -> 620 | I22: =I21+3 -> 51 | L22: 760 | M22: 620
D23: IGH ? (si oui = 0,95) --> | G23: =IF(est_igh="OUI",0.95,1) -> 1 | H23: =IF(est_igh="OUI",0.95,1) -> 1
D25: Migeo | E25: {=INDEX(E28:BF35,MATCH(zoneclim,D28:D35,0),MATCH(elevation,E27:G27,0)+D27)} -> 0
E26: =Enumération!C37 -> Maisons_individuelles_ou_accolées | H26: =Enumération!$D$33 -> Logement_collectif | K26: =Enumération!$E$33 -> Bureaux | N26: =Enumération!$F$33 -> Enseignement_primaire_ou_secondaire | Q26: =Enumération!$G$33 -> Médiathèques_et_bibliothèques | T26: =Enumération!$H$33 -> Bâtiments_universitaires_d'enseignement_et_de_recherche_et_bâtiments_d’enseignements_atypiques | W26: =Enumération!$I$33 -> Hôtels | Z26: =Enumération!$J$33 -> Etablissements_d'accueil_de_la_petite_enfance | AC26: =Enumération!$K$33 -> Restaurants | AF26: =Enumération!$L$33 -> Commerces | AI26: =Enumération!$M$33 -> Vestiaires seuls | AL26: =Enumération!$N$33 -> Etablissements_sanitaires_avec_hébergement | AO26: =Enumération!$O$33 -> Etablissements_de_santé | AR26: =Enumération!$P$33 -> Aérogares | AU26: =Enumération!$Q$33 -> Industries_ou_artisanats | AX26: =Enumération!$R$33 -> Etablissements_sportifs_municipaux_ou_scolaires | BA26: =Enumération!$S$33 -> Restaurants_scolaires | BD26: =Enumération!$T$33 -> Etablissements_sportifs_privés
D27: =VLOOKUP(Input_resultats!E4,D5:J22,6,FALSE) -> 3 | E27: =Calcul_bbio!E36 -> <400m | F27: =Calcul_bbio!F36 -> 400m-800m | G27: =Calcul_bbio!G36 -> >800m | H27: =E27 -> <400m | I27: =F27 -> 400m-800m | J27: =G27 -> >800m | K27: =H27 -> <400m | L27: =I27 -> 400m-800m | M27: =J27 -> >800m | N27: =K27 -> <400m | O27: =L27 -> 400m-800m | P27: =M27 -> >800m | Q27: <400m | R27: <400 | S27: >800m | T27: <400m | U27: 400m-800m | V27: >800m | W27: <400m | X27: 400m-800m | Y27: >800m | Z27: <400m | AA27: 400m-800m | AB27: >800m | AC27: <400m | AD27: 400m-800m | AE27: >800m | AF27: <400m | AG27: 400m-800m | AH27: >800m | AI27: <400m | AJ27: 400m-800m | AK27: >800m | AL27: <400m | AM27: 400m-800m | AN27: >800m | AO27: <400m | AP27: 400m-800m | AQ27: >800m | AR27: <400m | AS27: 400m-800m | AT27: >800m | AU27: <400m | AV27: 400m-800m | AW27: >800m | AX27: <400m | AY27: 400m-800m | AZ27: >800m | BA27: <400m | BB27: 400m-800m | BC27: >800m | BD27: <400m | BE27: 400m-800m | BF27: >800m
D28: H1a | E28: 0 | F28: 0 | G28: 0 | H28: 0 | I28: 0 | J28: 0 | K28: 0 | L28: 0 | M28: 0 | N28: 0 | O28: 0 | P28: 0 | Q28: 0 | R28: 0 | S28: 0 | T28: 0 | U28: 0 | V28: 0 | W28: 0 | X28: 0 | Y28: 0 | Z28: 0 | AA28: 0 | AB28: 0 | AC28: 0 | AD28: 0 | AE28: 0 | AF28: 0 | AG28: 0 | AH28: 0 | AI28: 0 | AJ28: 0 | AK28: 0 | AL28: 0 | AM28: 0 | AN28: 0 | AO28: 0 | AP28: 0 | AQ28: 0 | AR28: 0 | AS28: 0 | AT28: 0 | AU28: 0 | AV28: 0 | AW28: 0 | AX28: 0 | AY28: 0 | AZ28: 0 | BA28: 0 | BB28: 0 | BC28: 0 | BD28: 0 | BE28: 0 | BF28: 0
D29: H1b | E29: 0 | F29: 0 | G29: 0 | H29: 0 | I29: 0 | J29: 0 | K29: 0 | L29: 0 | M29: 0 | N29: 0 | O29: 0 | P29: 0 | Q29: 0 | R29: 0 | S29: 0 | T29: 0 | U29: 0 | V29: 0 | W29: 0 | X29: 0 | Y29: 0 | Z29: 0 | AA29: 0 | AB29: 0 | AC29: 0 | AD29: 0 | AE29: 0 | AF29: 0 | AG29: 0 | AH29: 0 | AI29: 0 | AJ29: 0 | AK29: 0 | AL29: 0 | AM29: 0 | AN29: 0 | AO29: 0 | AP29: 0 | AQ29: 0 | AR29: 0 | AS29: 0 | AT29: 0 | AU29: 0 | AV29: 0 | AW29: 0 | AX29: 0 | AY29: 0 | AZ29: 0 | BA29: 0 | BB29: 0 | BC29: 0 | BD29: 0 | BE29: 0 | BF29: 0
D30: H1c | E30: 0 | F30: 0 | G30: 0 | H30: 0 | I30: 0 | J30: 0 | K30: 0 | L30: 0 | M30: 0 | N30: 0 | O30: 0 | P30: 0 | Q30: 0 | R30: 0 | S30: 0 | T30: 0 | U30: 0 | V30: 0 | W30: 0 | X30: 0 | Y30: 0 | Z30: 0 | AA30: 0 | AB30: 0 | AC30: 0 | AD30: 0 | AE30: 0 | AF30: 0 | AG30: 0 | AH30: 0 | AI30: 0 | AJ30: 0 | AK30: 0 | AL30: 0 | AM30: 0 | AN30: 0 | AO30: 0 | AP30: 0 | AQ30: 0 | AR30: 0 | AS30: 0 | AT30: 0 | AU30: 0 | AV30: 0 | AW30: 0 | AX30: 0 | AY30: 0 | AZ30: 0 | BA30: 0 | BB30: 0 | BC30: 0 | BD30: 0 | BE30: 0 | BF30: 0
D31: H2a | E31: 0 | F31: 0 | G31: 0 | H31: 0 | I31: 0 | J31: 0 | K31: 0 | L31: 0 | M31: 0 | N31: 0 | O31: 0 | P31: 0 | Q31: 0 | R31: 0 | S31: 0 | T31: 0 | U31: 0 | V31: 0 | W31: 0 | X31: 0 | Y31: 0 | Z31: 0 | AA31: 0 | AB31: 0 | AC31: 0 | AD31: 0 | AE31: 0 | AF31: 0 | AG31: 0 | AH31: 0 | AI31: 0 | AJ31: 0 | AK31: 0 | AL31: 0 | AM31: 0 | AN31: 0 | AO31: 0 | AP31: 0 | AQ31: 0 | AR31: 0 | AS31: 0 | AT31: 0 | AU31: 0 | AV31: 0 | AW31: 0 | AX31: 0 | AY31: 0 | AZ31: 0 | BA31: 0 | BB31: 0 | BC31: 0 | BD31: 0 | BE31: 0 | BF31: 0
D32: H2b | E32: 0 | F32: 0 | G32: 0 | H32: 0 | I32: 0 | J32: 0 | K32: 0 | L32: 0 | M32: 0 | N32: 0 | O32: 0 | P32: 0 | Q32: 0 | R32: 0 | S32: 0 | T32: 0 | U32: 0 | V32: 0 | W32: 0 | X32: 0 | Y32: 0 | Z32: 0 | AA32: 0 | AB32: 0 | AC32: 0 | AD32: 0 | AE32: 0 | AF32: 0 | AG32: 0 | AH32: 0 | AI32: 0 | AJ32: 0 | AK32: 0 | AL32: 0 | AM32: 0 | AN32: 0 | AO32: 0 | AP32: 0 | AQ32: 0 | AR32: 0 | AS32: 0 | AT32: 0 | AU32: 0 | AV32: 0 | AW32: 0 | AX32: 0 | AY32: 0 | AZ32: 0 | BA32: 0 | BB32: 0 | BC32: 0 | BD32: 0 | BE32: 0 | BF32: 0
D33: H2c | E33: 0 | F33: 0 | G33: 0 | H33: 0 | I33: 0 | J33: 0 | K33: 0 | L33: 0 | M33: 0 | N33: 0 | O33: 0 | P33: 0 | Q33: 0 | R33: 0 | S33: 0 | T33: 0 | U33: 0 | V33: 0 | W33: 0 | X33: 0 | Y33: 0 | Z33: 0 | AA33: 0 | AB33: 0 | AC33: 0 | AD33: 0 | AE33: 0 | AF33: 0 | AG33: 0 | AH33: 0 | AI33: 0 | AJ33: 0 | AK33: 0 | AL33: 0 | AM33: 0 | AN33: 0 | AO33: 0 | AP33: 0 | AQ33: 0 | AR33: 0 | AS33: 0 | AT33: 0 | AU33: 0 | AV33: 0 | AW33: 0 | AX33: 0 | AY33: 0 | AZ33: 0 | BA33: 0 | BB33: 0 | BC33: 0 | BD33: 0 | BE33: 0 | BF33: 0
D34: H2d | E34: 30 | F34: 0 | G34: 0 | H34: 30 | I34: 0 | J34: 0 | K34: 50 | L34: 0 | M34: 0 | N34: 0 | O34: 0 | P34: 0 | Q34: 30 | R34: 0 | S34: 0 | T34: 30 | U34: 0 | V34: 0 | W34: 20 | X34: 0 | Y34: 0 | Z34: 0 | AA34: 0 | AB34: 0 | AC34: 0 | AD34: 0 | AE34: 0 | AF34: 0 | AG34: 0 | AH34: 0 | AI34: 0 | AJ34: 0 | AK34: 0 | AL34: 0 | AM34: 0 | AN34: 0 | AO34: 0 | AP34: 0 | AQ34: 0 | AR34: 0 | AS34: 0 | AT34: 0 | AU34: 0 | AV34: 0 | AW34: 0 | AX34: 0 | AY34: 0 | AZ34: 0 | BA34: 0 | BB34: 0 | BC34: 0 | BD34: 0 | BE34: 0 | BF34: 0
D35: H3 | E35: 30 | F35: 0 | G35: 0 | H35: 30 | I35: 0 | J35: 0 | K35: 50 | L35: 0 | M35: 0 | N35: 0 | O35: 0 | P35: 0 | Q35: 30 | R35: 0 | S35: 0 | T35: 30 | U35: 0 | V35: 0 | W35: 20 | X35: 0 | Y35: 0 | Z35: 0 | AA35: 0 | AB35: 0 | AC35: 0 | AD35: 0 | AE35: 0 | AF35: 0 | AG35: 0 | AH35: 0 | AI35: 0 | AJ35: 0 | AK35: 0 | AL35: 0 | AM35: 0 | AN35: 0 | AO35: 0 | AP35: 0 | AQ35: 0 | AR35: 0 | AS35: 0 | AT35: 0 | AU35: 0 | AV35: 0 | AW35: 0 | AX35: 0 | AY35: 0 | AZ35: 0 | BA35: 0 | BB35: 0 | BC35: 0 | BD35: 0 | BE35: 0 | BF35: 0
D37: Micombles | E37: =IF(usage=D5,(0.4*scombles)/sref,0) -> 0 | AC37: Maison indiv | AH37: Log collectf
D39: Misurf_moy | E39: =HLOOKUP("ICI",G42:Z43,2,FALSE) -> 0 | G39: =E26 -> Maisons_individuelles_ou_accolées | H39: =G39 -> Maisons_individuelles_ou_accolées | I39: =H26 -> Logement_collectif | J39: =I39 -> Logement_collectif | K39: =Enumération!E33 -> Bureaux | L39: =Enumération!F33 -> Enseignement_primaire_ou_secondaire | M39: =Enumération!G33 -> Médiathèques_et_bibliothèques | N39: =Enumération!H33 -> Bâtiments_universitaires_d'enseignement_et_de_recherche_et_bâtiments_d’enseignements_atypiques | O39: =Enumération!I33 -> Hôtels | P39: =Enumération!J33 -> Etablissements_d'accueil_de_la_petite_enfance | Q39: =Enumération!K33 -> Restaurants | R39: =Enumération!L33 -> Commerces | ... Z39: =Enumération!T33 -> Etablissements_sportifs_privés
G40: smoylgt<=120 | H40: smoylgt>120 | I40: smoylgt<=40 | J40: smoylgt>40
F41: surface → | G41: =smoylgt<=120 -> TRUE | H41: =smoylgt>120 -> FALSE | I41: =smoylgt<=40 -> FALSE | J41: =smoylgt>40 -> TRUE
F42: LA colonne → | G42: =IF(AND(usage=G39,Calcul_matiere!G41),"ICI","NON") -> NON | H42: =IF(AND(usage=H39,Calcul_matiere!H41),"ICI","NON") -> NON | I42: =IF(AND(usage=I39,Calcul_matiere!I41),"ICI","NON") -> NON | J42: =IF(AND(usage=J39,Calcul_matiere!J41),"ICI","NON") -> ICI | K42: =IF(usage=K39,"ICI","NON") -> NON | L42: =IF(AND(usage=L39,Calcul_matiere!L41),"ICI","NON") -> NON | M42: =IF(AND(usage=M39,Calcul_matiere!M41),"ICI","NON") -> NON | N42: =IF(AND(usage=N39,Calcul_matiere!N41),"ICI","NON") -> NON | O42: =IF(AND(usage=O39,Calcul_matiere!O41),"ICI","NON") -> NON | P42: =IF(AND(usage=P39,Calcul_matiere!P41),"ICI","NON") -> NON | Q42: =IF(AND(usage=Q39,Calcul_matiere!Q41),"ICI","NON") -> NON | R42: =IF(AND(usage=R39,Calcul_matiere!R41),"ICI","NON") -> NON | S42: =IF(AND(usage=S39,Calcul_matiere!S41),"ICI","NON") -> NON | ... Z42: =IF(AND(usage=Z39,Calcul_matiere!Z41),"ICI","NON") -> NON
F43: calcul → | G43: =0.36-((3.6*smoylgt)/1000) -> 0.132 | H43: -0.072 | I43: =(100-(2.5*smoylgt))/icconstructionmaxmoyen -> -0.08974359 | J43: 0 | K43: 0 | L43: 0 | M43: 0 | N43: 0 | O43: 0 | P43: 0 | Q43: 0 | R43: 0 | S43: 0 | T43: 0 | U43: 0 | V43: 0 | W43: 0 | X43: 0 | Y43: 0 | Z43: 0
D45: Misurf_Tot | E45: =HLOOKUP("ICI",G48:AE50,3,FALSE) -> -0.0875 | G45: =D5 -> Maisons_individuelles_ou_accolées | H45: =D6 -> Logement_collectif | I45: =H45 -> Logement_collectif | J45: =I45 -> Logement_collectif | K45: =D7 -> Bureaux | L45: =K45 -> Bureaux | M45: =D8 -> Enseignement_primaire_ou_secondaire | N45: =M45 -> Enseignement_primaire_ou_secondaire | O45: =Enumération!G33 -> Médiathèques_et_bibliothèques | P45: =Enumération!H33 -> Bâtiments_universitaires_d'enseignement_et_de_recherche_et_bâtiments_d’enseignements_atypiques | Q45: =Enumération!I33 -> Hôtels | R45: =Enumération!J33 -> Etablissements_d'accueil_de_la_petite_enfance | S45: =Enumération!K33 -> Restaurants | T45: =Enumération!L33 -> Commerces | U45: =Enumération!M33 -> Vestiaires seuls | V45: =Enumération!N33 -> Etablissements_sanitaires_avec_hébergement | ... Y45: =Enumération!Q33 -> Industries_ou_artisanats | Z45: =Y45 -> Industries_ou_artisanats | AA45: =Enumération!R33 -> Etablissements_sportifs_municipaux_ou_scolaires | AB45: =AA45 -> Etablissements_sportifs_municipaux_ou_scolaires | AC45: =Enumération!S33 -> Restaurants_scolaires | AD45: =Enumération!T33 -> Etablissements_sportifs_privés | AE45: =AD45 -> Etablissements_sportifs_privés
...

Sheet zone climatique
A1: Régions | B1: numéro | C1: département | D1: Valeur
A2: - | B2: - | C2: - | D2: -
A3: Auvergne-Rhône-Alpes | B3: 1 | C3: Ain | D3: H1c
A4: Hauts-de-France | B4: 2 | C4: Aisne | D4: H1a
A5: Auvergne-Rhône-Alpes | B5: 3 | C5: Allier | D5: H1c
A6: Provence-Alpes-Côte d'Azur | B6: 4 | C6: Alpes-de-Haute-Provence | D6: H2d
